<?xml version="1.0"?>

<robot name="mobile_robot">
  <material name="yellow" >
    <color rgba="0.9 0.85 0.2 0.8" />
  </material>
  
  <material name="black" >
    <color rgba="0.05 0.05 0.05 0.8" />
  </material>
  
  <link name="base_0" />
  
  <joint name="base_footprint" type="fixed">
    <parent link="base_0" />
    <child link="base_chassis" />
    <origin rpy="0.0 0.0 0.0" xyz="0.0 0.0 0.075" />
  </joint>
  
  <link name="base_chassis">
  	<origin rpy="0.0 0.0 0.0" xyz="0.0 0.0 0.0" />
  	<visual>
      <geometry>
        <box size="0.2 0.3 0.1" />
      </geometry>
      <material name="yellow" />
  	</visual>
  </link>

  <joint name="joint_left_drive_wheel" type="continuous">
    <parent link="base_chassis" />
    <child  link="left_drive_wheel" />
    <origin rpy="0.0 0.0 0.0" xyz="0.1125 0.075 -0.025" />
    <axis xyz="1.0 0.0 0.0" />
</joint>

  <link name="left_drive_wheel">
	<visual>
      <origin rpy="0.0 -1.57 0.0" xyz="0.0 0.0 0.0" />
      <geometry>
        <cylinder radius="0.05" length="0.025" />
      </geometry>
      <material name="black" />
	</visual>
  </link>

 <joint name="joint_right_drive_wheel" type="continuous">
    <parent link="base_chassis" />
    <child  link="right_drive_wheel" />
    <origin rpy="0.0 0.0 0.0" xyz="-0.1125 0.075 -0.025" />
    <axis xyz="1.0 0.0 0.0" />
</joint>

  <link name="right_drive_wheel">
	<visual>
      <origin rpy="0.0 1.57 0.0" xyz="0.0 0.0 0.0" />
      <geometry>
        <cylinder radius="0.05" length="0.025" />
      </geometry>
      <material name="black" />
	</visual>
  </link>

  <joint name="base_to_caster_right" type="fixed" >
    <parent link="base_chassis" />
    <child  link="caster_right" />
    <origin rpy="0.0 0.0 0.0" xyz="0.06 -0.1 -0.05" />
  </joint>

  <link name="caster_right" >
	<visual>
      <origin xyz="0.0 0.0 0.0" rpy="0.0 0.0 0.0" />
      <geometry>
        <sphere radius="0.025" />
      </geometry>
      <material name="black" />
	</visual>
  </link>

  <joint name="base_to_caster_left" type="fixed" >
    <parent link="base_chassis" />
    <child  link="caster_left" />
    <origin rpy="0.0 0.0 0.0" xyz="-0.06 -0.1 -0.05" />
  </joint>

  <link name="caster_left" >
	<visual>
      <origin xyz="0.0 0.0 0.0" rpy="0.0 0.0 0.0" />
      <geometry>
        <sphere radius="0.025" />
      </geometry>
      <material name="black" />
    </visual>
  </link>
</robot>